Workbook
Name Slicer_Age_Group: #N/A
Name Slicer_CreditCard: #N/A
Name Slicer_Education: #N/A
Name Slicer_Family_members: #N/A
Name Slicer_Income_Group: #N/A
Name Slicer_Online: #N/A
Name Slicer_Personal_Loan: #REF!
Name Slicer_Personal_Loan1: #REF!
Name Slicer_Personal_Loan2: #REF!
Name Slicer_Personal_Loan3: #REF!

Sheet Cleaning Log
A1: HSBC Personal Loan Dataset — Data Cleaning Log
A3: Summary of Checks Performed
A4: Check | B4: Finding | C4: Action Taken
A5: Duplicate rows / duplicate IDs | B5: 0 found | C5: No action needed
A6: Missing values | B6: 18 blanks in 'Family members' column | C6: Imputed with the column median (2) — cells highlighted yellow with a comment on each.
A7: Invalid ZIP codes | B7: 1 row (ID 385, row 1753) has a 4-digit ZIP (9307) instead of 5 | C7: Flagged in orange with a comment
A8: Legend
A9: Yellow fill | B9: Value was missing and has been imputed
A10: Orange fill | B10: Value looks invalid/suspicious — flagged for manual review, not altered

Sheet Raw Data
A1: ID | B1: Age (in years) | C1: Experience (in years) | D1: Income (in K/year) | E1: Income Categorical | F1: ZIP Code | G1: Family members | H1: CCAvg | I1: Education | J1: Mortgage | K1: Personal Loan | L1: Securities Account | M1: TD Account | N1: Online | O1: CreditCard
A2: 15 | B2: 67 | C2: 41 | D2: 112 | E2: =IF(D2<=50,"0-50",IF(D2<=100,"51-100","100+")) -> 100+ | F2: 91741 | G2: 1 | H2: 2 | I2: Undergraduate | J2: 0 | K2: No | L2: Yes | M2: No | N2: No | O2: No
A3: 1481 | B3: 67 | C3: 42 | D3: 32 | E3: =IF(D3<=50,"0-50",IF(D3<=100,"51-100","100+")) -> 0-50 | F3: 93943 | G3: 1 | H3: 1.1 | I3: Professional | J3: 0 | K3: No | L3: No | M3: No | N3: No | O3: Yes
A4: 1860 | B4: 67 | C4: 41 | D4: 20 | E4: =IF(D4<=50,"0-50",IF(D4<=100,"51-100","100+")) -> 0-50 | F4: 91741 | G4: 2 | H4: 0.4 | I4: Undergraduate | J4: 80 | K4: No | L4: No | M4: No | N4: No | O4: No
A5: 2847 | B5: 67 | C5: 43 | D5: 105 | E5: =IF(D5<=50,"0-50",IF(D5<=100,"51-100","100+")) -> 100+ | F5: 93711 | G5: 4 | H5: 1.7 | I5: Graduate | J5: 0 | K5: No | L5: No | M5: No | N5: Yes | O5: No
A6: 3265 | B6: 67 | C6: 41 | D6: 114 | E6: =IF(D6<=50,"0-50",IF(D6<=100,"51-100","100+")) -> 100+ | F6: 95616 | G6: 4 | H6: 2.4 | I6: Professional | J6: 0 | K6: No | L6: No | M6: No | N6: Yes | O6: No
A7: 3332 | B7: 67 | C7: 42 | D7: 21 | E7: =IF(D7<=50,"0-50",IF(D7<=100,"51-100","100+")) -> 0-50 | F7: 94607 | G7: 3 | H7: 0.1 | I7: Professional | J7: 0 | K7: No | L7: No | M7: No | N7: No | O7: Yes
A8: 3704 | B8: 67 | C8: 41 | D8: 78 | E8: =IF(D8<=50,"0-50",IF(D8<=100,"51-100","100+")) -> 51-100 | F8: 94301 | G8: 4 | H8: 2.4 | I8: Professional | J8: 0 | K8: No | L8: Yes | M8: No | N8: No | O8: No
A9: 3887 | B9: 67 | C9: 43 | D9: 79 | E9: =IF(D9<=50,"0-50",IF(D9<=100,"51-100","100+")) -> 51-100 | F9: 95616 | G9: 4 | H9: 1.7 | I9: Graduate | J9: 215 | K9: No | L9: No | M9: Yes | N9: Yes | O9: Yes
A10: 4173 | B10: 67 | C10: 42 | D10: 75 | E10: =IF(D10<=50,"0-50",IF(D10<=100,"51-100","100+")) -> 51-100 | F10: 90041 | G10: 4 | H10: 0.1 | I10: Graduate | J10: 182 | K10: No | L10: No | M10: No | N10: Yes | O10: No
A11: 4361 | B11: 67 | C11: 43 | D11: 41 | E11: =IF(D11<=50,"0-50",IF(D11<=100,"51-100","100+")) -> 0-50 | F11: 90024 | G11: 2 | H11: 1.1 | I11: Undergraduate | J11: 0 | K11: No | L11: No | M11: No | N11: No | O11: No
A12: 4452 | B12: 67 | C12: 41 | D12: 18 | E12: =IF(D12<=50,"0-50",IF(D12<=100,"51-100","100+")) -> 0-50 | F12: 92130 | G12: 2 | H12: 0.4 | I12: Undergraduate | J12: 0 | K12: No | L12: No | M12: No | N12: Yes | O12: No
A13: 4469 | B13: 67 | C13: 42 | D13: 51 | E13: =IF(D13<=50,"0-50",IF(D13<=100,"51-100","100+")) -> 51-100 | F13: 94117 | G13: 3 | H13: 2.2 | I13: Undergraduate | J13: 0 | K13: No | L13: No | M13: No | N13: Yes | O13: Yes
... A5001: 4412 | B5001: 23 | C5001: 2 | D5001: 75 | E5001: =IF(D5001<=50,"0-50",IF(D5001<=100,"51-100","100+")) -> 51-100 | F5001: 90291 | G5001: 2 | H5001: 1.8 | I5001: Graduate | J5001: 0 | K5001: No | L5001: No | M5001: No | N5001: Yes | O5001: Yes

Sheet Cleaned Data set
A1: ID | B1: Age (in years) | C1: Experience (in years) | D1: Income (in K/year) | E1: Income Categorical | F1: ZIP Code | G1: Family members | H1: CCAvg | I1: Education | J1: Mortgage | K1: Personal Loan | L1: Securities Account | M1: TD Account | N1: Online | O1: CreditCard | P1: Age Group | Q1: Income Group | R1: Mortgage Group | S1: Experience Group | T1: CC Avg Group
A2: 15 | B2: 67 | C2: 41 | D2: 112 | E2: =IF(D2<=50,"0-50",IF(D2<=100,"51-100","100+")) -> 100+ | F2: 91741 | G2: 1 | H2: 2 | I2: Undergraduate | J2: 0 | K2: No | L2: Yes | M2: No | N2: No | O2: No | P2: {=_xlfn.IFS( B2<30,"20-29", B2<40,"30-39", B2<50,"40-49", B2<60,"50-59", TRUE,"60+")} -> 60+ | Q2: {=_xlfn.IFS( D2<25,"0–24K", D2<50,"25–49K", D2<75,"50–74K", D2<100,"75–99K", D2<150,"100–149K", D2<200,"150–199K", TRUE,"200K+" )} -> 100–149K | R2: {=_xlfn.IFS( J2=0,"No Mortgage", J2<=100,"Low", J2<=300,"Medium", TRUE,"High" )} -> No Mortgage | S2: {=_xlfn.IFS( C2<10,"0-10", C2<20,"11-20", C2<30,"21-30", TRUE,"30+ yrs" )} -> 30+ yrs | T2: {=_xlfn.IFS( H2<1,"0-1", H2<2,"1-2", H2<3,"2-3", H2<4,"3-4", H2<5,"4-5", TRUE,"5+" )} -> 2-3
A3: 1481 | B3: 67 | C3: 42 | D3: 32 | E3: =IF(D3<=50,"0-50",IF(D3<=100,"51-100","100+")) -> 0-50 | F3: 93943 | G3: 1 | H3: 1.1 | I3: Professional | J3: 0 | K3: No | L3: No | M3: No | N3: No | O3: Yes | P3: {=_xlfn.IFS( B3<30,"20-29", B3<40,"30-39", B3<50,"40-49", B3<60,"50-59", TRUE,"60+")} -> 60+ | Q3: {=_xlfn.IFS( D3<25,"0–24K", D3<50,"25–49K", D3<75,"50–74K", D3<100,"75–99K", D3<150,"100–149K", D3<200,"150–199K", TRUE,"200K+" )} -> 25–49K | R3: {=_xlfn.IFS( J3=0,"No Mortgage", J3<=100,"Low", J3<=300,"Medium", TRUE,"High" )} -> No Mortgage | S3: {=_xlfn.IFS( C3<10,"0-10", C3<20,"11-20", C3<30,"21-30", TRUE,"30+ yrs" )} -> 30+ yrs | T3: {=_xlfn.IFS( H3<1,"0-1", H3<2,"1-2", H3<3,"2-3", H3<4,"3-4", H3<5,"4-5", TRUE,"5+" )} -> 1-2
A4: 1860 | B4: 67 | C4: 41 | D4: 20 | E4: =IF(D4<=50,"0-50",IF(D4<=100,"51-100","100+")) -> 0-50 | F4: 91741 | G4: 2 | H4: 0.4 | I4: Undergraduate | J4: 80 | K4: No | L4: No | M4: No | N4: No | O4: No | P4: {=_xlfn.IFS( B4<30,"20-29", B4<40,"30-39", B4<50,"40-49", B4<60,"50-59", TRUE,"60+")} -> 60+ | Q4: {=_xlfn.IFS( D4<25,"0–24K", D4<50,"25–49K", D4<75,"50–74K", D4<100,"75–99K", D4<150,"100–149K", D4<200,"150–199K", TRUE,"200K+" )} -> 0–24K | R4: {=_xlfn.IFS( J4=0,"No Mortgage", J4<=100,"Low", J4<=300,"Medium", TRUE,"High" )} -> Low | S4: {=_xlfn.IFS( C4<10,"0-10", C4<20,"11-20", C4<30,"21-30", TRUE,"30+ yrs" )} -> 30+ yrs | T4: {=_xlfn.IFS( H4<1,"0-1", H4<2,"1-2", H4<3,"2-3", H4<4,"3-4", H4<5,"4-5", TRUE,"5+" )} -> 0-1
A5: 2847 | B5: 67 | C5: 43 | D5: 105 | E5: =IF(D5<=50,"0-50",IF(D5<=100,"51-100","100+")) -> 100+ | F5: 93711 | G5: 4 | H5: 1.7 | I5: Graduate | J5: 0 | K5: No | L5: No | M5: No | N5: Yes | O5: No | P5: {=_xlfn.IFS( B5<30,"20-29", B5<40,"30-39", B5<50,"40-49", B5<60,"50-59", TRUE,"60+")} -> 60+ | Q5: {=_xlfn.IFS( D5<25,"0–24K", D5<50,"25–49K", D5<75,"50–74K", D5<100,"75–99K", D5<150,"100–149K", D5<200,"150–199K", TRUE,"200K+" )} -> 100–149K | R5: {=_xlfn.IFS( J5=0,"No Mortgage", J5<=100,"Low", J5<=300,"Medium", TRUE,"High" )} -> No Mortgage | S5: {=_xlfn.IFS( C5<10,"0-10", C5<20,"11-20", C5<30,"21-30", TRUE,"30+ yrs" )} -> 30+ yrs | T5: {=_xlfn.IFS( H5<1,"0-1", H5<2,"1-2", H5<3,"2-3", H5<4,"3-4", H5<5,"4-5", TRUE,"5+" )} -> 1-2
A6: 3265 | B6: 67 | C6: 41 | D6: 114 | E6: =IF(D6<=50,"0-50",IF(D6<=100,"51-100","100+")) -> 100+ | F6: 95616 | G6: 4 | H6: 2.4 | I6: Professional | J6: 0 | K6: No | L6: No | M6: No | N6: Yes | O6: No | P6: {=_xlfn.IFS( B6<30,"20-29", B6<40,"30-39", B6<50,"40-49", B6<60,"50-59", TRUE,"60+")} -> 60+ | Q6: {=_xlfn.IFS( D6<25,"0–24K", D6<50,"25–49K", D6<75,"50–74K", D6<100,"75–99K", D6<150,"100–149K", D6<200,"150–199K", TRUE,"200K+" )} -> 100–149K | R6: {=_xlfn.IFS( J6=0,"No Mortgage", J6<=100,"Low", J6<=300,"Medium", TRUE,"High" )} -> No Mortgage | S6: {=_xlfn.IFS( C6<10,"0-10", C6<20,"11-20", C6<30,"21-30", TRUE,"30+ yrs" )} -> 30+ yrs | T6: {=_xlfn.IFS( H6<1,"0-1", H6<2,"1-2", H6<3,"2-3", H6<4,"3-4", H6<5,"4-5", TRUE,"5+" )} -> 2-3
A7: 3332 | B7: 67 | C7: 42 | D7: 21 | E7: =IF(D7<=50,"0-50",IF(D7<=100,"51-100","100+")) -> 0-50 | F7: 94607 | G7: 3 | H7: 0.1 | I7: Professional | J7: 0 | K7: No | L7: No | M7: No | N7: No | O7: Yes | P7: {=_xlfn.IFS( B7<30,"20-29", B7<40,"30-39", B7<50,"40-49", B7<60,"50-59", TRUE,"60+")} -> 60+ | Q7: {=_xlfn.IFS( D7<25,"0–24K", D7<50,"25–49K", D7<75,"50–74K", D7<100,"75–99K", D7<150,"100–149K", D7<200,"150–199K", TRUE,"200K+" )} -> 0–24K | R7: {=_xlfn.IFS( J7=0,"No Mortgage", J7<=100,"Low", J7<=300,"Medium", TRUE,"High" )} -> No Mortgage | S7: {=_xlfn.IFS( C7<10,"0-10", C7<20,"11-20", C7<30,"21-30", TRUE,"30+ yrs" )} -> 30+ yrs | T7: {=_xlfn.IFS( H7<1,"0-1", H7<2,"1-2", H7<3,"2-3", H7<4,"3-4", H7<5,"4-5", TRUE,"5+" )} -> 0-1
A8: 3704 | B8: 67 | C8: 41 | D8: 78 | E8: =IF(D8<=50,"0-50",IF(D8<=100,"51-100","100+")) -> 51-100 | F8: 94301 | G8: 4 | H8: 2.4 | I8: Professional | J8: 0 | K8: No | L8: Yes | M8: No | N8: No | O8: No | P8: {=_xlfn.IFS( B8<30,"20-29", B8<40,"30-39", B8<50,"40-49", B8<60,"50-59", TRUE,"60+")} -> 60+ | Q8: {=_xlfn.IFS( D8<25,"0–24K", D8<50,"25–49K", D8<75,"50–74K", D8<100,"75–99K", D8<150,"100–149K", D8<200,"150–199K", TRUE,"200K+" )} -> 75–99K | R8: {=_xlfn.IFS( J8=0,"No Mortgage", J8<=100,"Low", J8<=300,"Medium", TRUE,"High" )} -> No Mortgage | S8: {=_xlfn.IFS( C8<10,"0-10", C8<20,"11-20", C8<30,"21-30", TRUE,"30+ yrs" )} -> 30+ yrs | T8: {=_xlfn.IFS( H8<1,"0-1", H8<2,"1-2", H8<3,"2-3", H8<4,"3-4", H8<5,"4-5", TRUE,"5+" )} -> 2-3
A9: 3887 | B9: 67 | C9: 43 | D9: 79 | E9: =IF(D9<=50,"0-50",IF(D9<=100,"51-100","100+")) -> 51-100 | F9: 95616 | G9: 4 | H9: 1.7 | I9: Graduate | J9: 215 | K9: No | L9: No | M9: Yes | N9: Yes | O9: Yes | P9: {=_xlfn.IFS( B9<30,"20-29", B9<40,"30-39", B9<50,"40-49", B9<60,"50-59", TRUE,"60+")} -> 60+ | Q9: {=_xlfn.IFS( D9<25,"0–24K", D9<50,"25–49K", D9<75,"50–74K", D9<100,"75–99K", D9<150,"100–149K", D9<200,"150–199K", TRUE,"200K+" )} -> 75–99K | R9: {=_xlfn.IFS( J9=0,"No Mortgage", J9<=100,"Low", J9<=300,"Medium", TRUE,"High" )} -> Medium | S9: {=_xlfn.IFS( C9<10,"0-10", C9<20,"11-20", C9<30,"21-30", TRUE,"30+ yrs" )} -> 30+ yrs | T9: {=_xlfn.IFS( H9<1,"0-1", H9<2,"1-2", H9<3,"2-3", H9<4,"3-4", H9<5,"4-5", TRUE,"5+" )} -> 1-2
A10: 4173 | B10: 67 | C10: 42 | D10: 75 | E10: =IF(D10<=50,"0-50",IF(D10<=100,"51-100","100+")) -> 51-100 | F10: 90041 | G10: 4 | H10: 0.1 | I10: Graduate | J10: 182 | K10: No | L10: No | M10: No | N10: Yes | O10: No | P10: {=_xlfn.IFS( B10<30,"20-29", B10<40,"30-39", B10<50,"40-49", B10<60,"50-59", TRUE,"60+")} -> 60+ | Q10: {=_xlfn.IFS( D10<25,"0–24K", D10<50,"25–49K", D10<75,"50–74K", D10<100,"75–99K", D10<150,"100–149K", D10<200,"150–199K", TRUE,"200K+" )} -> 75–99K | R10: {=_xlfn.IFS( J10=0,"No Mortgage", J10<=100,"Low", J10<=300,"Medium", TRUE,"High" )} -> Medium | S10: {=_xlfn.IFS( C10<10,"0-10", C10<20,"11-20", C10<30,"21-30", TRUE,"30+ yrs" )} -> 30+ yrs | T10: {=_xlfn.IFS( H10<1,"0-1", H10<2,"1-2", H10<3,"2-3", H10<4,"3-4", H10<5,"4-5", TRUE,"5+" )} -> 0-1
A11: 4361 | B11: 67 | C11: 43 | D11: 41 | E11: =IF(D11<=50,"0-50",IF(D11<=100,"51-100","100+")) -> 0-50 | F11: 90024 | G11: 2 | H11: 1.1 | I11: Undergraduate | J11: 0 | K11: No | L11: No | M11: No | N11: No | O11: No | P11: {=_xlfn.IFS( B11<30,"20-29", B11<40,"30-39", B11<50,"40-49", B11<60,"50-59", TRUE,"60+")} -> 60+ | Q11: {=_xlfn.IFS( D11<25,"0–24K", D11<50,"25–49K", D11<75,"50–74K", D11<100,"75–99K", D11<150,"100–149K", D11<200,"150–199K", TRUE,"200K+" )} -> 25–49K | R11: {=_xlfn.IFS( J11=0,"No Mortgage", J11<=100,"Low", J11<=300,"Medium", TRUE,"High" )} -> No Mortgage | S11: {=_xlfn.IFS( C11<10,"0-10", C11<20,"11-20", C11<30,"21-30", TRUE,"30+ yrs" )} -> 30+ yrs | T11: {=_xlfn.IFS( H11<1,"0-1", H11<2,"1-2", H11<3,"2-3", H11<4,"3-4", H11<5,"4-5", TRUE,"5+" )} -> 1-2
A12: 4452 | B12: 67 | C12: 41 | D12: 18 | E12: =IF(D12<=50,"0-50",IF(D12<=100,"51-100","100+")) -> 0-50 | F12: 92130 | G12: 2 | H12: 0.4 | I12: Undergraduate | J12: 0 | K12: No | L12: No | M12: No | N12: Yes | O12: No | P12: {=_xlfn.IFS( B12<30,"20-29", B12<40,"30-39", B12<50,"40-49", B12<60,"50-59", TRUE,"60+")} -> 60+ | Q12: {=_xlfn.IFS( D12<25,"0–24K", D12<50,"25–49K", D12<75,"50–74K", D12<100,"75–99K", D12<150,"100–149K", D12<200,"150–199K", TRUE,"200K+" )} -> 0–24K | R12: {=_xlfn.IFS( J12=0,"No Mortgage", J12<=100,"Low", J12<=300,"Medium", TRUE,"High" )} -> No Mortgage | S12: {=_xlfn.IFS( C12<10,"0-10", C12<20,"11-20", C12<30,"21-30", TRUE,"30+ yrs" )} -> 30+ yrs | T12: {=_xlfn.IFS( H12<1,"0-1", H12<2,"1-2", H12<3,"2-3", H12<4,"3-4", H12<5,"4-5", TRUE,"5+" )} -> 0-1
A13: 4469 | B13: 67 | C13: 42 | D13: 51 | E13: =IF(D13<=50,"0-50",IF(D13<=100,"51-100","100+")) -> 51-100 | F13: 94117 | G13: 3 | H13: 2.2 | I13: Undergraduate | J13: 0 | K13: No | L13: No | M13: No | N13: Yes | O13: Yes | P13: {=_xlfn.IFS( B13<30,"20-29", B13<40,"30-39", B13<50,"40-49", B13<60,"50-59", TRUE,"60+")} -> 60+ | Q13: {=_xlfn.IFS( D13<25,"0–24K", D13<50,"25–49K", D13<75,"50–74K", D13<100,"75–99K", D13<150,"100–149K", D13<200,"150–199K", TRUE,"200K+" )} -> 50–74K | R13: {=_xlfn.IFS( J13=0,"No Mortgage", J13<=100,"Low", J13<=300,"Medium", TRUE,"High" )} -> No Mortgage | S13: {=_xlfn.IFS( C13<10,"0-10", C13<20,"11-20", C13<30,"21-30", TRUE,"30+ yrs" )} -> 30+ yrs | T13: {=_xlfn.IFS( H13<1,"0-1", H13<2,"1-2", H13<3,"2-3", H13<4,"3-4", H13<5,"4-5", TRUE,"5+" )} -> 2-3
... A5001: 4412 | B5001: 23 | C5001: 2 | D5001: 75 | E5001: =IF(D5001<=50,"0-50",IF(D5001<=100,"51-100","100+")) -> 51-100 | F5001: 90291 | G5001: 2 | H5001: 1.8 | I5001: Graduate | J5001: 0 | K5001: No | L5001: No | M5001: No | N5001: Yes | O5001: Yes | P5001: {=_xlfn.IFS( B5001<30,"20-29", B5001<40,"30-39", B5001<50,"40-49", B5001<60,"50-59", TRUE,"60+")} -> 20-29 | Q5001: {=_xlfn.IFS( D5001<25,"0–24K", D5001<50,"25–49K", D5001<75,"50–74K", D5001<100,"75–99K", D5001<150,"100–149K", D5001<200,"150–199K", TRUE,"200K+" )} -> 75–99K | R5001: {=_xlfn.IFS( J5001=0,"No Mortgage", J5001<=100,"Low", J5001<=300,"Medium", TRUE,"High" )} -> No Mortgage | S5001: {=_xlfn.IFS( C5001<10,"0-10", C5001<20,"11-20", C5001<30,"21-30", TRUE,"30+ yrs" )} -> 0-10 | T5001: {=_xlfn.IFS( H5001<1,"0-1", H5001<2,"1-2", H5001<3,"2-3", H5001<4,"3-4", H5001<5,"4-5", TRUE,"5+" )} -> 1-2

Sheet EDA-1
C1: UNIVARIATE ANALYSIS
S5: Row Labels | T5: Count of Education
S6: Undergraduate | T6: 2096
S7: Professional | T7: 1501
S8: Graduate | T8: 1403
S9: Grand Total | T9: 5000
S13: Row Labels | T13: Count of ID
S14: 1 | T14: 1464
S15: 2 | T15: 1310
S16: 3 | T16: 1009
S17: 4 | T17: 1217
S18: Grand Total | T18: 5000
S22: Row Labels | T22: Count of Personal Loan
S23: No | T23: 4520
S24: Yes | T24: 480
S25: Grand Total | T25: 5000
S29: Row Labels | T29: Count of ID
S30: High | T30: 201
S31: Low | T31: 282
S32: Medium | T32: 1055
S33: No Mortgage | T33: 3462
S34: Grand Total | T34: 5000
S41: Row Labels | T41: Count of ID
S42: 0-1 | T42: 1683
S43: 1-2 | T43: 1376
S44: 2-3 | T44: 1039
S45: 3-4 | T45: 319
S46: 4-5 | T46: 219
S47: 5+ | T47: 364
S48: Grand Total | T48: 5000
S53: Row Labels | T53: Count of ID
S54: No | T54: 2016
S55: Yes | T55: 2984
S56: Grand Total | T56: 5000
S61: Row Labels | T61: Count of ID
S62: No | T62: 3530
S63: Yes | T63: 1470
S64: Grand Total | T64: 5000
S69: Row Labels | T69: Count of ID
S70: No | T70: 4698
...

Sheet EDA 2
I2: BIVARIATE ANALYSIS
O3: Count of ID | P3: Column Labels
O4: Row Labels | P4: No | Q4: Yes | R4: Grand Total
O5: 0–24K | P5: 608 | R5: 608
O6: 100–149K | P6: 550 | Q6: 219 | R6: 769
O7: 150–199K | P7: 217 | Q7: 217 | R7: 434
O8: 200K+ | P8: 16 | Q8: 3 | R8: 19
O9: 25–49K | P9: 1261 | R9: 1261
O10: 50–74K | P10: 1036 | Q10: 6 | R10: 1042
O11: 75–99K | P11: 832 | Q11: 35 | R11: 867
O12: Grand Total | P12: 4520 | Q12: 480 | R12: 5000
O19: Count of ID | P19: Column Labels
O20: Row Labels | P20: No | Q20: Yes | R20: Grand Total
O21: Graduate | P21: 1221 | Q21: 182 | R21: 1403
O22: Professional | P22: 1296 | Q22: 205 | R22: 1501
O23: Undergraduate | P23: 2003 | Q23: 93 | R23: 2096
O24: Grand Total | P24: 4520 | Q24: 480 | R24: 5000
O29: Count of ID | P29: Column Labels
O30: Row Labels | P30: No | Q30: Yes | R30: Grand Total
O31: No | P31: 1827 | Q31: 189 | R31: 2016
O32: Yes | P32: 2693 | Q32: 291 | R32: 2984
O33: Grand Total | P33: 4520 | Q33: 480 | R33: 5000
O38: Count of ID | P38: Column Labels
O39: Row Labels | P39: No | Q39: Yes | R39: Grand Total
O40: No | P40: 3193 | Q40: 337 | R40: 3530
O41: Yes | P41: 1327 | Q41: 143 | R41: 1470
O42: Grand Total | P42: 4520 | Q42: 480 | R42: 5000
O49: Count of ID | P49: Column Labels
O50: Row Labels | P50: No | Q50: Yes | R50: Grand Total
O51: 1 | P51: 1358 | Q51: 106 | R51: 1464
O52: 2 | P52: 1202 | Q52: 108 | R52: 1310
O53: 3 | P53: 876 | Q53: 133 | R53: 1009
O54: 4 | P54: 1084 | Q54: 133 | R54: 1217
O55: Grand Total | P55: 4520 | Q55: 480 | R55: 5000

Sheet EDA 3
K1: Online | L1: (All)
R2: MULTI-VARIATE ANALYSIS
K3: Count of Personal Loan | L3: Column Labels
K4: Row Labels | L4: Graduate | M4: Professional | N4: Undergraduate | O4: Grand Total
K5: 0–24K | L5: 196 | M5: 206 | N5: 206 | O5: 608
K6: 100–149K | L6: 133 | M6: 147 | N6: 489 | O6: 769
K7: 150–199K | L7: 83 | M7: 100 | N7: 251 | O7: 434
K8: 200K+ | L8: 1 | M8: 2 | N8: 16 | O8: 19
K9: 25–49K | L9: 445 | M9: 414 | N9: 402 | O9: 1261
K10: 50–74K | L10: 275 | M10: 376 | N10: 391 | O10: 1042
K11: 75–99K | L11: 270 | M11: 256 | N11: 341 | O11: 867
K12: Grand Total | L12: 1403 | M12: 1501 | N12: 2096 | O12: 5000
K14: CreditCard | L14: (All)
K16: Count of ID | L16: Column Labels
K17: Row Labels | L17: 0–24K | M17: 100–149K | N17: 150–199K | O17: 200K+ | P17: 25–49K | Q17: 50–74K | R17: 75–99K | S17: Grand Total
K18: High | M18: 79 | N18: 84 | O18: 3 | R18: 35 | S18: 201
K19: Low | L19: 104 | M19: 21 | N19: 5 | P19: 87 | Q19: 41 | R19: 24 | S19: 282
K20: Medium | L20: 90 | M20: 113 | N20: 61 | O20: 3 | P20: 313 | Q20: 281 | R20: 194 | S20: 1055
K21: No Mortgage | L21: 414 | M21: 556 | N21: 284 | O21: 13 | P21: 861 | Q21: 720 | R21: 614 | S21: 3462
K22: Grand Total | L22: 608 | M22: 769 | N22: 434 | O22: 19 | P22: 1261 | Q22: 1042 | R22: 867 | S22: 5000
K25: Personal Loan | L25: (All)
K27: Count of ID | L27: Column Labels
K28: Row Labels | L28: 0–24K | M28: 100–149K | N28: 150–199K | O28: 200K+ | P28: 25–49K | Q28: 50–74K | R28: 75–99K | S28: Grand Total
K29: 1 | L29: 177 | M29: 289 | N29: 151 | O29: 5 | P29: 367 | Q29: 232 | R29: 243 | S29: 1464
K30: 2 | L30: 157 | M30: 275 | N30: 165 | O30: 13 | P30: 265 | Q30: 194 | R30: 241 | S30: 1310
K31: 3 | L31: 98 | M31: 93 | N31: 64 | O31: 1 | P31: 287 | Q31: 304 | R31: 162 | S31: 1009
K32: 4 | L32: 176 | M32: 112 | N32: 54 | P32: 342 | Q32: 312 | R32: 221 | S32: 1217
K33: Grand Total | L33: 608 | M33: 769 | N33: 434 | O33: 19 | P33: 1261 | Q33: 1042 | R33: 867 | S33: 5000

Sheet Pivot tables & Charts
A2: Pivot Table 1 – Total Loan Accepted vs Not Accepted
A4: Business Question
A6: How many customers accepted and rejected the personal loan?
A8: Row Labels | B8: Count of Personal Loan
A9: No | B9: 4520
A10: Yes | B10: 480
A11: Grand Total | B11: 5000
A13: Pivot Table 2 – Income Category vs Loan Acceptance
A15: Business Question
A17: Which income category has the highest loan acceptance rate?
O19: Average of Income (in K/year) | Q19: Average of Age (in years)
A20: Count of Personal Loan | B20: Column Labels | O20: 73.7742 | Q20: 45.3384
A21: Row Labels | B21: No | C21: Yes | D21: Grand Total
A22: 0-50 | B22: 1 | C22: 0 | D22: 1
A23: 51-100 | B23: 0.97758805 | C23: 0.022411953 | D23: 1 | O23: Average of Mortgage | Q23: Average of CCAvg
A24: 100+ | B24: 0.63861386 | C24: 0.36138614 | D24: 1 | O24: 56.4988 | Q24: 1.937938
A25: Grand Total | B25: 0.904 | C25: 0.096 | D25: 1
A28: Pivot Table 3 – Education vs Loan Acceptance
A30: Business Question
A32: Are highly educated customers more likely to accept loans?
A34: Count of Personal Loan | B34: Column Labels
A35: Row Labels | B35: No | C35: Yes | D35: Grand Total
A36: Professional | B36: 0.86342438 | C36: 0.13657562 | D36: 1
A37: Graduate | B37: 0.87027798 | C37: 0.12972202 | D37: 1
A38: Undergraduate | B38: 0.95562977 | C38: 0.044370229 | D38: 1
A39: Grand Total | B39: 0.904 | C39: 0.096 | D39: 1
A41: Pivot Table 4 – Online Banking vs Loan Acceptance
A43: Business Question
A45: Does online banking influence loan acceptance?
A47: Count of Personal Loan | B47: Column Labels
A48: Row Labels | B48: No | C48: Yes | D48: Grand Total
A49: No | B49: 0.90625 | C49: 0.09375 | D49: 1
A50: Yes | B50: 0.90247989 | C50: 0.097520107 | D50: 1
A51: Grand Total | B51: 0.904 | C51: 0.096 | D51: 1
A53: Pivot Table 5 – Credit Card vs Loan Acceptance
A55: Business Question
A57: Does credit card usage influence loan acceptance?
A59: Count of Personal Loan | B59: Column Labels
A60: Row Labels | B60: No | C60: Yes | D60: Grand Total
A61: No | B61: 0.90453258 | C61: 0.095467422 | D61: 1
...

Sheet KPI
D3: KPIs
D6: TOTAL CUSTOMERS | E6: =GETPIVOTDATA("Personal Loan",'Pivot tables & Charts'!$A$8) -> 5000
D7: LOAN ACCEPTORS | E7: =GETPIVOTDATA("Personal Loan",'Pivot tables & Charts'!$A$8,"Personal Loan","Yes") -> 480
D8: LOAN ACCEPTANCE RATE | E8: =E7/E6 -> 0.096
D9: AVG INCOME(K/Year) | E9: =GETPIVOTDATA("Income (in K/year)",'Pivot tables & Charts'!$O$19) -> 73.7742
D10: Avg Age (Years) | E10: =GETPIVOTDATA("Age (in years)",'Pivot tables & Charts'!$Q$19) -> 45.3384
D11: Avg Mortgage | E11: =GETPIVOTDATA("Mortgage",'Pivot tables & Charts'!$O$23) -> 56.4988
D12: CC Avg (Monthly) | E12: =GETPIVOTDATA("CCAvg",'Pivot tables & Charts'!$Q$23) -> 1.937938

Sheet Dashboard
AU7: TOTAL CUSTOMERS | AV7: =GETPIVOTDATA("Personal Loan",'Pivot tables & Charts'!$A$8) -> 5000
AU8: LOAN ACCEPTORS | AV8: =GETPIVOTDATA("Personal Loan",'Pivot tables & Charts'!$A$8,"Personal Loan","Yes") -> 480
AU9: LOAN ACCEPTANCE RATE | AV9: =AV8/AV7 -> 0.096
AU10: AVG INCOME(K/Year) | AV10: =GETPIVOTDATA("Income (in K/year)",'Pivot tables & Charts'!$O$19) -> 73.7742
AU11: Avg Age (Years) | AV11: =GETPIVOTDATA("Age (in years)",'Pivot tables & Charts'!$Q$19) -> 45.3384
AU12: Avg Mortgage | AV12: =GETPIVOTDATA("Mortgage",'Pivot tables & Charts'!$O$23) -> 56.4988
AU13: CC Avg (Monthly) | AV13: =GETPIVOTDATA("CCAvg",'Pivot tables & Charts'!$Q$23) -> 1.937938

Sheet Key Insights
